<?xml version="1.0" encoding="utf-8"  ?>
<robot name="cartpole_v0">
	<!-- * * * Link Definitions * * * -->
	<!-- * * * Define World Link to fix the foot rail to the world * * * -->
	<link name="world"/>
	<link name="bar_link">
		<visual>
			<origin xyz="0 0 0.4" rpy="0 0 0"/>
			<geometry>
				<box size="0.05 0.05 0.8"/>
			</geometry>
			<material name="brown">
				<color rgba="0.9 0.8 0.6 1.0"/>
			</material>
		</visual>
		
		<inertial>
			<origin xyz="0 0 0.4" rpy="0 0 0"/>
			<mass value="1"/>
			<inertia ixx="0.0535416666667" ixy="0.0" ixz="0.0" iyy="0.0535416666667" iyz="0.0" izz="0.000416666666667"/>
		</inertial>
	</link>
	<gazebo reference="bar_link">
		<material>Gazebo/Orange</material>
	</gazebo>
	<link name="base_link">
		<visual>
			<origin xyz="0 0 0.2" rpy="0 0 0"/>
			<geometry>
				<box size="0.4 0.2 0.2"/>
			</geometry>
			<material name="black">
				<color rgba="0 0 0 1.0"/>
			</material>
		</visual>
		<collision>
			<origin xyz="0 0 0.2" rpy="0 0 0"/>
			<geometry>
				<box size="0.4 0.2 0.2"/>
			</geometry>
		</collision>
		<inertial>
			<origin xyz="0 0 0.2" rpy="0 0 0"/>
			<mass value="2.5"/>
			<inertia ixx="0.0166666666667" ixy="0.0" ixz="0.0" iyy="0.0416666666667" iyz="0.0" izz="0.0416666666667"/>
		</inertial>
	</link>
	<gazebo reference="base_link">
		<kp>1000.0</kp>
		<kd>1000.0</kd>
		<mu1>0.5</mu1>
		<mu2>0.5</mu2>
		<material>Gazebo/Black</material>
	</gazebo>
	<link name="foot_link">
		<visual>
			<origin xyz="0 0 0.05" rpy="0 0 0"/>
			<geometry>
				<box size="6 0.025 0.1"/>
			</geometry>
			<material name="white">
				<color rgba="1 1 1 1.0"/>
			</material>
		</visual>
		<collision>
			<origin xyz="0 0 0.05" rpy="0 0 0"/>
			<geometry>
				<box size="6 0.025 0.1"/>
			</geometry>
		</collision>
		<inertial>
			<origin xyz="0 0 0.05" rpy="0 0 0"/>
			<mass value="5"/>
			<inertia ixx="0.00442708333333" ixy="0.0" ixz="0.0" iyy="15.0041666667" iyz="0.0" izz="15.0002604167"/>
		</inertial>
	</link>
	<gazebo reference="foot_link">
		<kp>1000.0</kp>
		<kd>1000.0</kd>
		<mu1>0.5</mu1>
		<mu2>0.5</mu2>
		<material>Gazebo/White</material>
	</gazebo>

	


	<!-- * * * Joint Definitions * * * -->
	<joint name="cartpole_joint" type="revolute">
		<parent link="base_link"/>
		<child link="bar_link"/>
		<origin xyz="0 -0.2 0.32" rpy="0 0 0"/>
		
		<limit lower="-6.28" upper="6.28" effort="0" velocity="1000"/>
		<axis xyz="0 1 0"/>
	</joint>
	<joint name="foot_joint" type="prismatic">
		<parent link="foot_link"/>
		<child link="base_link"/>
		<limit lower="-2.0" upper="2.0" effort="2000000" velocity="100000"/>
	</joint>
	<joint name="fixed" type="fixed">
		<parent link="world"/>
		<child link="foot_link"/>
	</joint>














	
	<!-- * * * Transmission Definitions * * * -->
	
	<transmission name="foot_joint_trans">
		<type>transmission_interface/SimpleTransmission</type>
		<joint name="foot_joint">
			<hardwareInterface>hardware_interface/EffortJointInterface</hardwareInterface>
		</joint>
		<actuator name="foot_jointMotor">
			<hardwareInterface>hardware_interface/EffortJointInterface</hardwareInterface>
			<mechanicalReduction>1</mechanicalReduction>
		</actuator>
	</transmission>
	<ros2_control name="GazeboSystem" type="system">
		<hardware>
			<plugin>gazebo_ros2_control/GazeboSystem</plugin>
		</hardware>
		<joint name="foot_joint">
			<command_interface name="velocity"/>
			<command_interface name="position"/>

			<state_interface name="velocity"/>
			<state_interface name="position"/>
		</joint>
		<joint name="cartpole_joint">
			<command_interface name="velocity"/>
			<command_interface name="position"/>

			<state_interface name="velocity"/>
			<state_interface name="position"/>
		</joint>
	</ros2_control>
	<gazebo>
		<plugin name="gazebo_ros2_control" filename="libgazebo_ros2_control.so">
			<parameters>$(find moving_cube2)/config/cartpole_v0_velocity.yaml</parameters>
		</plugin>
	</gazebo>
</robot>